[2022-12-05T07:27:25.493+0000] {taskinstance.py:1165} INFO - ðŸ¤ª Dependencies all met for <TaskInstance: get_raw_data_from_sources.get_raw_data_from_mysql_sources scheduled__2022-12-03T19:00:00+00:00 [queued]>
[2022-12-05T07:27:25.502+0000] {taskinstance.py:1165} INFO - ðŸ¤ª Dependencies all met for <TaskInstance: get_raw_data_from_sources.get_raw_data_from_mysql_sources scheduled__2022-12-03T19:00:00+00:00 [queued]>
[2022-12-05T07:27:25.503+0000] {taskinstance.py:1362} INFO - ðŸ¤ª 
--------------------------------------------------------------------------------
[2022-12-05T07:27:25.504+0000] {taskinstance.py:1363} INFO - ðŸ¤ª Starting attempt 2 of 4
[2022-12-05T07:27:25.504+0000] {taskinstance.py:1364} INFO - ðŸ¤ª 
--------------------------------------------------------------------------------
[2022-12-05T07:27:25.522+0000] {taskinstance.py:1383} INFO - ðŸ¤ª Executing <Task(PythonOperator): get_raw_data_from_mysql_sources> on 2022-12-03 19:00:00+00:00
[2022-12-05T07:27:25.526+0000] {standard_task_runner.py:55} INFO - ðŸ¤ª Started process 683 to run task
[2022-12-05T07:27:25.529+0000] {standard_task_runner.py:82} INFO - ðŸ¤ª Running: ['airflow', 'tasks', 'run', 'get_raw_data_from_sources', 'get_raw_data_from_mysql_sources', 'scheduled__2022-12-03T19:00:00+00:00', '--job-id', '4', '--raw', '--subdir', 'DAGS_FOLDER/ingest_dwh_daily.py', '--cfg-path', '/tmp/tmpq0igqq5_']
[2022-12-05T07:27:25.531+0000] {standard_task_runner.py:83} INFO - ðŸ¤ª Job 4: Subtask get_raw_data_from_mysql_sources
[2022-12-05T07:27:25.579+0000] {task_command.py:376} INFO - ðŸ¤ª Running <TaskInstance: get_raw_data_from_sources.get_raw_data_from_mysql_sources scheduled__2022-12-03T19:00:00+00:00 [running]> on host 2387a8df1781
[2022-12-05T07:27:25.623+0000] {taskinstance.py:1590} INFO - ðŸ¤ª Exporting the following env vars:
AIRFLOW_CTX_DAG_EMAIL=gp.data@galaxy.com.vn
AIRFLOW_CTX_DAG_OWNER=data_team
AIRFLOW_CTX_DAG_ID=get_raw_data_from_sources
AIRFLOW_CTX_TASK_ID=get_raw_data_from_mysql_sources
AIRFLOW_CTX_EXECUTION_DATE=2022-12-03T19:00:00+00:00
AIRFLOW_CTX_TRY_NUMBER=2
AIRFLOW_CTX_DAG_RUN_ID=scheduled__2022-12-03T19:00:00+00:00
[2022-12-05T07:27:25.625+0000] {logging_mixin.py:137} INFO - ðŸ¤ª Connecting to the MySQL database...
[2022-12-05T07:27:25.635+0000] {logging_mixin.py:137} INFO - ðŸ¤ª Database connection closed.
[2022-12-05T07:27:25.642+0000] {logging_mixin.py:137} INFO - ðŸ¤ª the dataframe is inserted
[2022-12-05T07:27:25.642+0000] {logging_mixin.py:137} INFO - ðŸ¤ª Connecting to the MySQL database...
[2022-12-05T07:27:25.647+0000] {logging_mixin.py:137} INFO - ðŸ¤ª Database connection closed.
[2022-12-05T07:27:25.651+0000] {logging_mixin.py:137} INFO - ðŸ¤ª the dataframe is inserted
[2022-12-05T07:27:25.652+0000] {logging_mixin.py:137} INFO - ðŸ¤ª Connecting to the MySQL database...
[2022-12-05T07:27:25.656+0000] {logging_mixin.py:137} INFO - ðŸ¤ª Database connection closed.
[2022-12-05T07:27:25.661+0000] {logging_mixin.py:137} INFO - ðŸ¤ª the dataframe is inserted
[2022-12-05T07:27:25.661+0000] {logging_mixin.py:137} INFO - ðŸ¤ª Connecting to the MySQL database...
[2022-12-05T07:27:25.664+0000] {logging_mixin.py:137} INFO - ðŸ¤ª (1142, "SELECT command denied to user 'report_admin'@'172.18.0.2' for table 'menus'")
[2022-12-05T07:27:25.665+0000] {logging_mixin.py:137} INFO - ðŸ¤ª Database connection closed.
[2022-12-05T07:27:25.669+0000] {taskinstance.py:1851} ERROR - ðŸ¤ª Task failed with exception
Traceback (most recent call last):
  File "/opt/bitnami/python/lib/python3.8/site-packages/airflow/operators/python.py", line 175, in execute
    return_value = self.execute_callable()
  File "/opt/bitnami/python/lib/python3.8/site-packages/airflow/operators/python.py", line 193, in execute_callable
    return self.python_callable(*self.op_args, **self.op_kwargs)
  File "/airflow/dags/controller/get_raw_data_from_mysql_source.py", line 36, in get_raw_data_from_mysql_source
    execute_values(conn, data, table)
  File "/airflow/dags/controller/source_controller.py", line 8, in execute_values
    tuples = [tuple(x) for x in df.to_numpy()]
AttributeError: 'NoneType' object has no attribute 'to_numpy'
[2022-12-05T07:27:25.677+0000] {taskinstance.py:1401} INFO - ðŸ¤ª Marking task as UP_FOR_RETRY. dag_id=get_raw_data_from_sources, task_id=get_raw_data_from_mysql_sources, execution_date=20221203T190000, start_date=20221205T072725, end_date=20221205T072725
[2022-12-05T07:27:25.694+0000] {standard_task_runner.py:100} ERROR - ðŸ¤ª Failed to execute job 4 for task get_raw_data_from_mysql_sources ('NoneType' object has no attribute 'to_numpy'; 683)
[2022-12-05T07:27:25.743+0000] {local_task_job.py:159} INFO - ðŸ¤ª Task exited with return code 1
[2022-12-05T07:27:25.761+0000] {taskinstance.py:2623} INFO - ðŸ¤ª 0 downstream tasks scheduled from follow-on schedule check
