[2022-12-11T06:06:36.601+0000] {taskinstance.py:1165} INFO - ðŸ¤ª Dependencies all met for <TaskInstance: update_dwh_daily.check_update_mysql_source scheduled__2022-12-09T19:30:00+00:00 [queued]>
[2022-12-11T06:06:36.608+0000] {taskinstance.py:1165} INFO - ðŸ¤ª Dependencies all met for <TaskInstance: update_dwh_daily.check_update_mysql_source scheduled__2022-12-09T19:30:00+00:00 [queued]>
[2022-12-11T06:06:36.609+0000] {taskinstance.py:1362} INFO - ðŸ¤ª 
--------------------------------------------------------------------------------
[2022-12-11T06:06:36.610+0000] {taskinstance.py:1363} INFO - ðŸ¤ª Starting attempt 1 of 4
[2022-12-11T06:06:36.611+0000] {taskinstance.py:1364} INFO - ðŸ¤ª 
--------------------------------------------------------------------------------
[2022-12-11T06:06:36.625+0000] {taskinstance.py:1383} INFO - ðŸ¤ª Executing <Task(PythonOperator): check_update_mysql_source> on 2022-12-09 19:30:00+00:00
[2022-12-11T06:06:36.629+0000] {standard_task_runner.py:55} INFO - ðŸ¤ª Started process 180 to run task
[2022-12-11T06:06:36.632+0000] {standard_task_runner.py:82} INFO - ðŸ¤ª Running: ['airflow', 'tasks', 'run', 'update_dwh_daily', 'check_update_mysql_source', 'scheduled__2022-12-09T19:30:00+00:00', '--job-id', '10', '--raw', '--subdir', 'DAGS_FOLDER/update_dwh_daily.py', '--cfg-path', '/tmp/tmpi_6ws43_']
[2022-12-11T06:06:36.634+0000] {standard_task_runner.py:83} INFO - ðŸ¤ª Job 10: Subtask check_update_mysql_source
[2022-12-11T06:06:36.708+0000] {task_command.py:376} INFO - ðŸ¤ª Running <TaskInstance: update_dwh_daily.check_update_mysql_source scheduled__2022-12-09T19:30:00+00:00 [running]> on host 2557b583fff6
[2022-12-11T06:06:36.798+0000] {taskinstance.py:1590} INFO - ðŸ¤ª Exporting the following env vars:
AIRFLOW_CTX_DAG_EMAIL=gp.data@galaxy.com.vn
AIRFLOW_CTX_DAG_OWNER=data_team
AIRFLOW_CTX_DAG_ID=update_dwh_daily
AIRFLOW_CTX_TASK_ID=check_update_mysql_source
AIRFLOW_CTX_EXECUTION_DATE=2022-12-09T19:30:00+00:00
AIRFLOW_CTX_TRY_NUMBER=1
AIRFLOW_CTX_DAG_RUN_ID=scheduled__2022-12-09T19:30:00+00:00
[2022-12-11T06:06:36.812+0000] {logging_mixin.py:137} INFO - ðŸ¤ª Start checking for updated data from source Mysql - Table: users
[2022-12-11T06:06:36.826+0000] {logging_mixin.py:137} INFO - ðŸ¤ª Found 0 updated records
[2022-12-11T06:06:36.827+0000] {logging_mixin.py:137} INFO - ðŸ¤ª Start updating DWH data - Table: users
[2022-12-11T06:06:36.829+0000] {logging_mixin.py:137} INFO - ðŸ¤ª Finished update DWH data - Table: users
[2022-12-11T06:06:36.829+0000] {logging_mixin.py:137} INFO - ðŸ¤ª Start checking for updated data from source Mysql - Table: orders
[2022-12-11T06:06:36.834+0000] {logging_mixin.py:137} INFO - ðŸ¤ª Found 0 updated records
[2022-12-11T06:06:36.835+0000] {logging_mixin.py:137} INFO - ðŸ¤ª Start updating DWH data - Table: orders
[2022-12-11T06:06:36.836+0000] {taskinstance.py:1851} ERROR - ðŸ¤ª Task failed with exception
Traceback (most recent call last):
  File "/opt/bitnami/python/lib/python3.8/site-packages/airflow/operators/python.py", line 175, in execute
    return_value = self.execute_callable()
  File "/opt/bitnami/python/lib/python3.8/site-packages/airflow/operators/python.py", line 193, in execute_callable
    return self.python_callable(*self.op_args, **self.op_kwargs)
  File "/airflow/dags/processing/check_update_mysql_source.py", line 40, in check_update_mysql_source
    update_dwh_data(mysql_handler=mysql_handler, data=data, table=table['table'])
  File "/airflow/dags/processing/check_update_mysql_source.py", line 16, in update_dwh_data
    dwh_handler.action_db(action='update', data=data, table=table)
  File "/airflow/dags/db_handler/dwh_handler.py", line 72, in action_db
    return self._change_data(data, table)
  File "/airflow/dags/db_handler/dwh_handler.py", line 37, in _change_data
    cur = self.dwh_connection.cursor()
psycopg2.InterfaceError: connection already closed
[2022-12-11T06:06:36.848+0000] {taskinstance.py:1401} INFO - ðŸ¤ª Marking task as UP_FOR_RETRY. dag_id=update_dwh_daily, task_id=check_update_mysql_source, execution_date=20221209T193000, start_date=20221211T060636, end_date=20221211T060636
[2022-12-11T06:06:36.864+0000] {standard_task_runner.py:100} ERROR - ðŸ¤ª Failed to execute job 10 for task check_update_mysql_source (connection already closed; 180)
[2022-12-11T06:06:36.885+0000] {local_task_job.py:159} INFO - ðŸ¤ª Task exited with return code 1
[2022-12-11T06:06:36.903+0000] {taskinstance.py:2623} INFO - ðŸ¤ª 0 downstream tasks scheduled from follow-on schedule check
